2023-11-28 12:25:19 ERROR Unable to initialize WebDriver
2023-11-28 12:25:19 ERROR 
Traceback (most recent call last):
  File "/home/runner/work/SeleniumCapital/SeleniumCapital/pages/base_page.py", line 82, in inner_function
    return func(*args, **kwargs)
           ^^^^^^^^^^^^^^^^^^^^^
  File "/home/runner/work/SeleniumCapital/SeleniumCapital/pages/base_page.py", line 390, in element_is_visible
    return Wait(self.browser, timeout).until(
           ^^^^^^^^^^^^^^^^^^^^^^^^^^^^^^^^^^
  File "/home/runner/.cache/pypoetry/virtualenvs/testcapitalcom-cIj6ROMf-py3.11/lib/python3.11/site-packages/selenium/webdriver/support/wait.py", line 101, in until
    raise TimeoutException(message, screen, stacktrace)
selenium.common.exceptions.TimeoutException: Message: 
Stacktrace:
#0 0x55b5086245e3 <unknown>
#1 0x55b5082e70b7 <unknown>
#2 0x55b508334f53 <unknown>
#3 0x55b508335051 <unknown>
#4 0x55b50837a9c4 <unknown>
#5 0x55b50835bf1d <unknown>
#6 0x55b508377b3d <unknown>
#7 0x55b50835bcc3 <unknown>
#8 0x55b5083270e4 <unknown>
#9 0x55b5083280ae <unknown>
#10 0x55b5085eace1 <unknown>
#11 0x55b5085eeb7e <unknown>
#12 0x55b5085d84b5 <unknown>
#13 0x55b5085ef7d6 <unknown>
#14 0x55b5085bbdbf <unknown>
#15 0x55b508612748 <unknown>
#16 0x55b508612917 <unknown>
#17 0x55b508623773 <unknown>
#18 0x7f1b74894ac3 <unknown>

2023-11-28 12:25:25 ERROR Unable to initialize WebDriver
2023-11-28 12:25:25 ERROR no such execution context
  (Session info: chrome=119.0.6045.159)
Traceback (most recent call last):
  File "/home/runner/work/SeleniumCapital/SeleniumCapital/pages/base_page.py", line 82, in inner_function
    return func(*args, **kwargs)
           ^^^^^^^^^^^^^^^^^^^^^
  File "/home/runner/work/SeleniumCapital/SeleniumCapital/pages/base_page.py", line 605, in wait_for_target_url
    return Wait(self.browser, timeout).until(
           ^^^^^^^^^^^^^^^^^^^^^^^^^^^^^^^^^^
  File "/home/runner/.cache/pypoetry/virtualenvs/testcapitalcom-cIj6ROMf-py3.11/lib/python3.11/site-packages/selenium/webdriver/support/wait.py", line 92, in until
    value = method(self._driver)
            ^^^^^^^^^^^^^^^^^^^^
  File "/home/runner/.cache/pypoetry/virtualenvs/testcapitalcom-cIj6ROMf-py3.11/lib/python3.11/site-packages/selenium/webdriver/support/expected_conditions.py", line 94, in _predicate
    return url in driver.current_url
                  ^^^^^^^^^^^^^^^^^^
  File "/home/runner/.cache/pypoetry/virtualenvs/testcapitalcom-cIj6ROMf-py3.11/lib/python3.11/site-packages/selenium/webdriver/remote/webdriver.py", line 436, in current_url
    return self.execute(Command.GET_CURRENT_URL)["value"]
           ^^^^^^^^^^^^^^^^^^^^^^^^^^^^^^^^^^^^^
  File "/home/runner/.cache/pypoetry/virtualenvs/testcapitalcom-cIj6ROMf-py3.11/lib/python3.11/site-packages/selenium/webdriver/remote/webdriver.py", line 346, in execute
    self.error_handler.check_response(response)
  File "/home/runner/.cache/pypoetry/virtualenvs/testcapitalcom-cIj6ROMf-py3.11/lib/python3.11/site-packages/selenium/webdriver/remote/errorhandler.py", line 229, in check_response
    raise exception_class(message, screen, stacktrace)
selenium.common.exceptions.WebDriverException: Message: no such execution context
  (Session info: chrome=119.0.6045.159)
Stacktrace:
#0 0x55b5086245e3 <unknown>
#1 0x55b5082e6f0d <unknown>
#2 0x55b5082cdc12 <unknown>
#3 0x55b5082cb4be <unknown>
#4 0x55b5082cbe39 <unknown>
#5 0x55b5082dd1d9 <unknown>
#6 0x55b5082f44c1 <unknown>
#7 0x55b5082fa13b <unknown>
#8 0x55b5082cc5ce <unknown>
#9 0x55b5082f4157 <unknown>
#10 0x55b508377d42 <unknown>
#11 0x55b50835bcc3 <unknown>
#12 0x55b5083270e4 <unknown>
#13 0x55b5083280ae <unknown>
#14 0x55b5085eace1 <unknown>
#15 0x55b5085eeb7e <unknown>
#16 0x55b5085d84b5 <unknown>
#17 0x55b5085ef7d6 <unknown>
#18 0x55b5085bbdbf <unknown>
#19 0x55b508612748 <unknown>
#20 0x55b508612917 <unknown>
#21 0x55b508623773 <unknown>
#22 0x7f1b74894ac3 <unknown>